<robot name="my_robot">
    <!-- to specify colours -->
    <material name="orange">
        <color rgba="1 0.5 0 1"/>
    </material>
    <material name="black">
        <color rgba="0 0 0 1"/>
    </material>

    <!-- links -->
    <link name="chassis">
        <visual>
            <geometry>
                <box size="1 0.5 0.1"/>
            </geometry>
            <material name="orange"/>
        </visual>
        <collision>
            <geometry>
                <box size="1 0.5 0.1"/>
            </geometry>
        </collision>
        <inertial>
            <mass value="10"/>
            <inertia ixx="0.22" ixy="0" ixz="0" iyy="0.84" iyz="0" izz="1.04"/>
        </inertial>
    </link>

    <link name="left_wheel">
        <visual>
            <geometry>
                <cylinder length="0.1" radius="0.3"/>
            </geometry>
            <origin rpy="-1.57075 0 0" xyz="0 -0.25 0"/>
            <material name="black"/>
        </visual>
        <collision>
            <geometry>
                <cylinder length="0.1" radius="0.3"/>
            </geometry>
            <origin rpy="-1.57075 0 0" xyz="0 -0.25 0"/>
        </collision>
        <inertial>
            <mass value="4"/>
            <inertia ixx="0.09" ixy="0" ixz="0" iyy="0.09" iyz="0" izz="0.18"/> 
        </inertial>
    </link>

    <link name="right_wheel">
        <visual>
            <geometry>
                <cylinder length="0.1" radius="0.3"/>
            </geometry>
            <origin rpy="1.57075 0 0" xyz="0 0.25 0"/>
            <material name="black"/>
        </visual>
        <collision>
            <geometry>
                <cylinder length="0.1" radius="0.3"/>
            </geometry>
            <origin rpy="1.57075 0 0" xyz="0 0.25 0"/>
        </collision>
        <inertial>
            <mass value="4"/>
            <inertia ixx="0.09" ixy="0" ixz="0" iyy="0.09" iyz="0" izz="0.18"/>
        </inertial>
    </link>
    
    <!-- joints -->
    <joint name="left_wheel_to_chassis" type="continuous">
        <parent link="chassis"/>
        <child link="left_wheel"/>
        <axis xyz="0 1 0"/>
    </joint>

    <joint name="right_wheel_to_chassis" type="continuous">
        <parent link="chassis"/>
        <child link="right_wheel"/>
        <axis xyz="0 1 0"/>
    </joint>
</robot>