<sdf version='1.10'>
  <world name='empty'>
    <physics name='1ms' type='ignored'>
      <max_step_size>0.001</max_step_size>
      <real_time_factor>1</real_time_factor>
      <real_time_update_rate>1000</real_time_update_rate>
    </physics>
    <plugin name='gz::sim::systems::Physics' filename='gz-sim-physics-system'/>
    <plugin name='gz::sim::systems::UserCommands' filename='gz-sim-user-commands-system'/>
    <plugin name='gz::sim::systems::SceneBroadcaster' filename='gz-sim-scene-broadcaster-system'/>
    <plugin name='gz::sim::systems::Contact' filename='gz-sim-contact-system'/>
    <gravity>0 0 -9.8000000000000007</gravity>
    <magnetic_field>5.5644999999999998e-06 2.2875799999999999e-05 -4.2388400000000002e-05</magnetic_field>
    <atmosphere type='adiabatic'/>
    <scene>
      <ambient>0.400000006 0.400000006 0.400000006 1</ambient>
      <background>0.699999988 0.699999988 0.699999988 1</background>
      <shadows>true</shadows>
    </scene>
    <model name='Baylands_terrain'>
      <pose>-2.1075200000000001 5.22173 -1.3 0 0 0</pose>
      <static>true</static>
      <link name='body3'>
        <visual name='visual'>
          <geometry>
            <mesh>
              <uri>model://baylands_terrain/media/baylands_03.DAE</uri>
            </mesh>
          </geometry>
        </visual>
        <collision name='collision'>
          <geometry>
            <mesh>
              <uri>model://baylands_terrain/media/baylands_03.DAE</uri>
            </mesh>
          </geometry>
        </collision>
        <pose>0 0 0 0 0 0</pose>
        <inertial>
          <pose>0 0 0 0 0 0</pose>
          <mass>1</mass>
          <inertia>
            <ixx>1</ixx>
            <ixy>0</ixy>
            <ixz>0</ixz>
            <iyy>1</iyy>
            <iyz>0</iyz>
            <izz>1</izz>
          </inertia>
        </inertial>
        <enable_wind>false</enable_wind>
      </link>
      <self_collide>false</self_collide>
    </model>
    <model name='robot'>
      <link name='link_1'>
        <pose>0 0 0 0 0 0</pose>
        <inertial>
          <mass>1</mass>
          <inertia>
            <ixx>0.16666700000000001</ixx>
            <ixy>0</ixy>
            <ixz>0</ixz>
            <iyy>0.16666700000000001</iyy>
            <iyz>0</iyz>
            <izz>0.16666700000000001</izz>
          </inertia>
          <pose>0 0 0 0 0 0</pose>
        </inertial>
        <self_collide>false</self_collide>
        <kinematic>false</kinematic>
        <gravity>true</gravity>
        <visual name='visual'>
          <pose>0 0 0 0 0 0</pose>
          <geometry>
            <box>
              <size>0.29999999999999999 1 0.10000000000000001</size>
            </box>
          </geometry>
          <material>
            <lighting>true</lighting>
            <script>
              <uri>file://media/materials/scripts/gazebo.material</uri>
              <name>Gazebo/Grey</name>
            </script>
            <shader type='pixel'>
              <normal_map>__default__</normal_map>
            </shader>
            <ambient>0.300000012 0.100000001 0 1</ambient>
            <diffuse>1 0.600000024 0 1</diffuse>
            <specular>1 1 1 1</specular>
            <emissive>0 0 0 1</emissive>
          </material>
          <transparency>0</transparency>
          <cast_shadows>true</cast_shadows>
        </visual>
        <collision name='collision'>
          <laser_retro>0</laser_retro>
          <max_contacts>10</max_contacts>
          <pose>0 0 0 0 0 0</pose>
          <geometry>
            <box>
              <size>0.29999999999999999 1 0.10000000000000001</size>
            </box>
          </geometry>
          <surface>
            <friction>
              <ode>
                <mu>1</mu>
                <mu2>1</mu2>
                <fdir1>0 0 0</fdir1>
                <slip1>0</slip1>
                <slip2>0</slip2>
              </ode>
              <torsional>
                <coefficient>1</coefficient>
                <patch_radius>0</patch_radius>
                <surface_radius>0</surface_radius>
                <use_patch_radius>true</use_patch_radius>
                <ode>
                  <slip>0</slip>
                </ode>
              </torsional>
            </friction>
            <bounce>
              <restitution_coefficient>0</restitution_coefficient>
              <threshold>1000000</threshold>
            </bounce>
            <contact>
              <collide_without_contact>false</collide_without_contact>
              <collide_without_contact_bitmask>1</collide_without_contact_bitmask>
              <collide_bitmask>1</collide_bitmask>
              <ode>
                <soft_cfm>0</soft_cfm>
                <soft_erp>0.20000000000000001</soft_erp>
                <kp>10000000000000</kp>
                <kd>1</kd>
                <max_vel>0.01</max_vel>
                <min_depth>0</min_depth>
              </ode>
              <bullet>
                <split_impulse>true</split_impulse>
                <split_impulse_penetration_threshold>-0.01</split_impulse_penetration_threshold>
                <soft_cfm>0</soft_cfm>
                <soft_erp>0.20000000000000001</soft_erp>
                <kp>10000000000000</kp>
                <kd>1</kd>
              </bullet>
            </contact>
          </surface>
        </collision>
        <enable_wind>false</enable_wind>
      </link>
      <link name='link_2'>
        <pose>-1.7763568394002505e-15 -0.5500190000000007 -4.4408920985006262e-16 1.5702149994728891 1.4043270402514456 -0.00057329102985684353</pose>
        <inertial>
          <mass>1</mass>
          <inertia>
            <ixx>0.14583299999999999</ixx>
            <ixy>0</ixy>
            <ixz>0</ixz>
            <iyy>0.14583299999999999</iyy>
            <iyz>0</iyz>
            <izz>0.125</izz>
          </inertia>
          <pose>0 0 0 0 0 0</pose>
        </inertial>
        <self_collide>false</self_collide>
        <kinematic>false</kinematic>
        <visual name='visual'>
          <pose>0 0 0 0 0 0</pose>
          <geometry>
            <cylinder>
              <radius>0.20000000000000001</radius>
              <length>0.10000000000000001</length>
            </cylinder>
          </geometry>
          <material>
            <lighting>true</lighting>
            <script>
              <uri>file://media/materials/scripts/gazebo.material</uri>
              <name>Gazebo/Grey</name>
            </script>
            <shader type='pixel'>
              <normal_map>__default__</normal_map>
            </shader>
            <ambient>0.300000012 0.300000012 0.300000012 1</ambient>
            <diffuse>0.699999988 0.699999988 0.699999988 1</diffuse>
            <specular>0.00999999978 0.00999999978 0.00999999978 1</specular>
            <emissive>0 0 0 1</emissive>
          </material>
          <transparency>0</transparency>
          <cast_shadows>true</cast_shadows>
        </visual>
        <collision name='collision'>
          <laser_retro>0</laser_retro>
          <max_contacts>10</max_contacts>
          <pose>0 0 0 0 0 0</pose>
          <geometry>
            <cylinder>
              <radius>0.20000000000000001</radius>
              <length>0.10000000000000001</length>
            </cylinder>
          </geometry>
          <surface>
            <friction>
              <ode>
                <mu>1</mu>
                <mu2>1</mu2>
                <fdir1>0 0 0</fdir1>
                <slip1>0</slip1>
                <slip2>0</slip2>
              </ode>
              <torsional>
                <coefficient>1</coefficient>
                <patch_radius>0</patch_radius>
                <surface_radius>0</surface_radius>
                <use_patch_radius>true</use_patch_radius>
                <ode>
                  <slip>0</slip>
                </ode>
              </torsional>
            </friction>
            <bounce>
              <restitution_coefficient>0</restitution_coefficient>
              <threshold>1000000</threshold>
            </bounce>
            <contact>
              <collide_without_contact>false</collide_without_contact>
              <collide_without_contact_bitmask>1</collide_without_contact_bitmask>
              <collide_bitmask>1</collide_bitmask>
              <ode>
                <soft_cfm>0</soft_cfm>
                <soft_erp>0.20000000000000001</soft_erp>
                <kp>10000000000000</kp>
                <kd>1</kd>
                <max_vel>0.01</max_vel>
                <min_depth>0</min_depth>
              </ode>
              <bullet>
                <split_impulse>true</split_impulse>
                <split_impulse_penetration_threshold>-0.01</split_impulse_penetration_threshold>
                <soft_cfm>0</soft_cfm>
                <soft_erp>0.20000000000000001</soft_erp>
                <kp>10000000000000</kp>
                <kd>1</kd>
              </bullet>
            </contact>
          </surface>
        </collision>
        <enable_wind>false</enable_wind>
      </link>
      <link name='link_2_clone'>
        <pose>0 0.55001899999999893 0 -0.14811062203273181 1.7685072150170594e-17 1.4458774689438952e-16</pose>
        <inertial>
          <mass>1</mass>
          <inertia>
            <ixx>0.14583299999999999</ixx>
            <ixy>0</ixy>
            <ixz>0</ixz>
            <iyy>0.14583299999999999</iyy>
            <iyz>0</iyz>
            <izz>0.125</izz>
          </inertia>
          <pose>0 0 0 0 0 0</pose>
        </inertial>
        <self_collide>false</self_collide>
        <kinematic>false</kinematic>
        <visual name='visual'>
          <pose>0 0 0 0 0 0</pose>
          <geometry>
            <cylinder>
              <radius>0.20000000000000001</radius>
              <length>0.10000000000000001</length>
            </cylinder>
          </geometry>
          <material>
            <lighting>true</lighting>
            <script>
              <uri>file://media/materials/scripts/gazebo.material</uri>
              <name>Gazebo/Grey</name>
            </script>
            <shader type='pixel'>
              <normal_map>__default__</normal_map>
            </shader>
            <ambient>0.300000012 0.300000012 0.300000012 1</ambient>
            <diffuse>0.699999988 0.699999988 0.699999988 1</diffuse>
            <specular>0.00999999978 0.00999999978 0.00999999978 1</specular>
            <emissive>0 0 0 1</emissive>
          </material>
          <transparency>0</transparency>
          <cast_shadows>true</cast_shadows>
        </visual>
        <collision name='collision'>
          <laser_retro>0</laser_retro>
          <max_contacts>10</max_contacts>
          <pose>0 0 0 0 0 0</pose>
          <geometry>
            <cylinder>
              <radius>0.20000000000000001</radius>
              <length>0.10000000000000001</length>
            </cylinder>
          </geometry>
          <surface>
            <friction>
              <ode>
                <mu>1</mu>
                <mu2>1</mu2>
                <fdir1>0 0 0</fdir1>
                <slip1>0</slip1>
                <slip2>0</slip2>
              </ode>
              <torsional>
                <coefficient>1</coefficient>
                <patch_radius>0</patch_radius>
                <surface_radius>0</surface_radius>
                <use_patch_radius>true</use_patch_radius>
                <ode>
                  <slip>0</slip>
                </ode>
              </torsional>
            </friction>
            <bounce>
              <restitution_coefficient>0</restitution_coefficient>
              <threshold>1000000</threshold>
            </bounce>
            <contact>
              <collide_without_contact>false</collide_without_contact>
              <collide_without_contact_bitmask>1</collide_without_contact_bitmask>
              <collide_bitmask>1</collide_bitmask>
              <ode>
                <soft_cfm>0</soft_cfm>
                <soft_erp>0.20000000000000001</soft_erp>
                <kp>10000000000000</kp>
                <kd>1</kd>
                <max_vel>0.01</max_vel>
                <min_depth>0</min_depth>
              </ode>
              <bullet>
                <split_impulse>true</split_impulse>
                <split_impulse_penetration_threshold>-0.01</split_impulse_penetration_threshold>
                <soft_cfm>0</soft_cfm>
                <soft_erp>0.20000000000000001</soft_erp>
                <kp>10000000000000</kp>
                <kd>1</kd>
              </bullet>
            </contact>
          </surface>
        </collision>
        <enable_wind>false</enable_wind>
      </link>
      <joint name='link_1_JOINT_0' type='revolute'>
        <parent>link_1</parent>
        <child>link_2</child>
        <pose>0 0 -1.11022e-16 0 0 0</pose>
        <axis>
          <xyz>0 0 1</xyz>
          <limit>
            <lower>-1.7976900000000001e+308</lower>
            <upper>1.7976900000000001e+308</upper>
            <effort>inf</effort>
            <velocity>inf</velocity>
            <stiffness>100000000</stiffness>
            <dissipation>1</dissipation>
          </limit>
          <dynamics>
            <spring_reference>0</spring_reference>
            <spring_stiffness>0</spring_stiffness>
            <damping>0</damping>
            <friction>0</friction>
          </dynamics>
        </axis>
        <physics>
          <ode>
            <limit>
              <cfm>0</cfm>
              <erp>0.20000000000000001</erp>
            </limit>
            <suspension>
              <cfm>0</cfm>
              <erp>0.20000000000000001</erp>
            </suspension>
          </ode>
        </physics>
      </joint>
      <joint name='link_1_JOINT_1' type='revolute'>
        <parent>link_1</parent>
        <child>link_2_clone</child>
        <pose>0 0 1.11022e-16 0 0 0</pose>
        <axis>
          <xyz>1 0 0</xyz>
          <limit>
            <lower>-1.7976900000000001e+308</lower>
            <upper>1.7976900000000001e+308</upper>
            <effort>inf</effort>
            <velocity>inf</velocity>
            <stiffness>100000000</stiffness>
            <dissipation>1</dissipation>
          </limit>
          <dynamics>
            <spring_reference>0</spring_reference>
            <spring_stiffness>0</spring_stiffness>
            <damping>0</damping>
            <friction>0</friction>
          </dynamics>
        </axis>
        <physics>
          <ode>
            <limit>
              <cfm>0</cfm>
              <erp>0.20000000000000001</erp>
            </limit>
            <suspension>
              <cfm>0</cfm>
              <erp>0.20000000000000001</erp>
            </suspension>
          </ode>
        </physics>
      </joint>
      <static>false</static>
      <allow_auto_disable>true</allow_auto_disable>
      <pose>3.5490517693508052 -19.155738217562057 -0.45072004655350056 -3.0553441010792404 0.0020285865865247404 2.3924283933094275</pose>
      <self_collide>false</self_collide>
    </model>
    <light name='sun' type='directional'>
      <pose>0 0 10 0 0 0</pose>
      <cast_shadows>true</cast_shadows>
      <intensity>1</intensity>
      <direction>-0.5 0.10000000000000001 -0.90000000000000002</direction>
      <diffuse>0.800000012 0.800000012 0.800000012 1</diffuse>
      <specular>0.200000003 0.200000003 0.200000003 1</specular>
      <attenuation>
        <range>1000</range>
        <linear>0.0099999997764825821</linear>
        <constant>0.89999997615814209</constant>
        <quadratic>0.0010000000474974513</quadratic>
      </attenuation>
      <spot>
        <inner_angle>0</inner_angle>
        <outer_angle>0</outer_angle>
        <falloff>0</falloff>
      </spot>
    </light>
  </world>
</sdf>
